Traceback (most recent call last):
  File "/home/lucia.trastulla/miniconda3/envs/py38/lib/python3.8/site-packages/pandas/core/indexes/base.py", line 3361, in get_loc
    return self._engine.get_loc(casted_key)
  File "pandas/_libs/index.pyx", line 76, in pandas._libs.index.IndexEngine.get_loc
  File "pandas/_libs/index.pyx", line 108, in pandas._libs.index.IndexEngine.get_loc
  File "pandas/_libs/hashtable_class_helper.pxi", line 5198, in pandas._libs.hashtable.PyObjectHashTable.get_item
  File "pandas/_libs/hashtable_class_helper.pxi", line 5206, in pandas._libs.hashtable.PyObjectHashTable.get_item
KeyError: 'substance'

The above exception was the direct cause of the following exception:

Traceback (most recent call last):
  File "src/extract_chembl_id.py", line 27, in <module>
    compound_names = input_table['substance'].unique().tolist()
  File "/home/lucia.trastulla/miniconda3/envs/py38/lib/python3.8/site-packages/pandas/core/frame.py", line 3458, in __getitem__
    indexer = self.columns.get_loc(key)
  File "/home/lucia.trastulla/miniconda3/envs/py38/lib/python3.8/site-packages/pandas/core/indexes/base.py", line 3363, in get_loc
    raise KeyError(key) from err
KeyError: 'substance'

Attaching package: ‘dplyr’

The following objects are masked from ‘package:stats’:

    filter, lag

The following objects are masked from ‘package:base’:

    intersect, setdiff, setequal, union

Error in ArgumentParser(description = "Associate ATC to a compound based on chemb ID match") : 
  could not find function "ArgumentParser"
Execution halted
/cm/local/apps/slurm/var/spool/job1167581/slurm_script: line 32: --atc_compounds_json: command not found
/cm/local/apps/slurm/var/spool/job1167581/slurm_script: line 33: --atc_csv: command not found
/cm/local/apps/slurm/var/spool/job1167581/slurm_script: line 34: --out: command not found
